Workbook

Sheet CASE INPUTS
B1: INSTRUCTIONS BEFORE STARTING THE SET UP
B2: * SEND THE PROJECTIONS LOAD TO DMS. STEPS ON HOW TO DO IT IS ON TAB 6
B3: * ENSURE THIS IS A REGULAR SET UP NOT A STATE SET UP
B4: * ADD ALL NECESARRY INPUTS FIRST IN "CASE INPUTS" TAB
B5: * COPY PASTE EXCEL FILE FROM CLIENT INTO "DATA" TAB
B7: OBTAIN INPUTS FROM CASE DETAILS
A8: CLOSING DATE | B8: 46199
A9: PROJECT STABILIZATION DATE | B9: 47239
A10: VCODE | B10: westrmt
A11: DATE TODAY | B11: =TEXT(TODAY(),"mm/dd/yyyy") -> 07/30/2026
A12: REGION
A13: vVENDOR | B13: mtbank | C13: <-- GET Vvendor FOR LOAN LENDER IN VENDOR SCREEN IF NO vVENDOR IN VENDOR SCREEN ADD VENDOR AS LENDER
A14: STATUS
A31: RENTS REFERENCE
A32: LI-Studio
A33: LI-1BR
A34: LI-2BR
A35: LI-3BR
A36: LI-4BR
A37: LI-5BR
A38: LI-6BR
A39: LI-7BR
A40: LI-8BR
A41: LI-9BR
... A56: Other

Sheet DATA
A1: General Information and Financing Assumptions | V1: VERSION 3.0 6/9/2015
A2: West Tremont Senior | O2: Printed: | P2: 46210.287 | Q2: 46210.287 | T2: Page 1
A4: Property Information | F4: Project Dates | K4: Base year DSCR
A5: Project Name | B5: West Tremont Senior | F5: Model Start Date | I5: 46174 | K5: Income net of Vacancy | M5: 3058756 | O5: Tax Exempt Bond Proceeds | R5: 0
A6: City | B6: Bronx | F6: LT Partnership Close | I6: 46174 | K6: Other Income Adjustments | M6: 0 | O6: Less: Non-Eligible Uses Funded by Bonds | R6: 0
A7: County | B7: Bronx | F7: Construction Start Date | I7: 46174 | K7: Operating Expenses | M7: -1000064 | O7: Other Adjustments | R7: 0
A8: State | B8: NY | F8: Construction Term (months) | I8: 27 | K8: Real Estate Tax Abatement | M8: 0 | O8: Other Adjustments | R8: 0
A9: Number of Total Units | B9: 97 | C9: Number of Rehabilitated Units | E9: 0 | F9: Construction Completion Date - Final Bldg. | I9: 46997 | K9: Management Fee | M9: -118819 | O9: Total Bond Proceeds | R9: 0
A10: Number of Qualified Units | B10: 96 | C10: Number of Non-Qualified Units | E10: 0 | F10: Construction Completion Date - First Bldg. | I10: 46997 | K10: Other Expense Adjustments | M10: 0
A11: Qualified Managers Unit | B11: 1 | C11: Number of Market Unit | E11: 0 | F11: Operations Start Date | I11: 46997 | K11: Replacement Reserves | M11: -38800 | O11: Aggregate Basis and Land
A12: Number of Buildings - LIHTC | B12: 1 | C12: Bldgs - Other | D12: 0 | F12: Months in First year of Operations | I12: 4 | K12: Base year NOI | M12: 1901073 | O12: Other Adjustments | R12: 0
A13: Commercial Space - square footage | B13: 0 | F13: First Tax Credit Month | I13: 47119 | K13: Base year debt Service | M13: 1509852 | O13: Total Aggregate Basis and Land | R13: 0
A14: New Construction/Rehabilitation | B14: New Construction | C14: 0 | D14: Scattered Site | F14: Lease up Starts | I14: 46997 | K14: Base year DCR | M14: 1.2591122
A15: Property Type | B15: High-Rise | C15: 0 | D15: No | E15: 0 | F15: Lease up Period (months) | I15: 6 | K15: Income to Exp + Hard Debt Ratio | M15: 1.1466601
A16: Market Type | B16: Urban | D16: Special Needs | F16: Leases per Month - Absorption: | I16: 16.166667 | Q16: Construction | R16: Permanent
A17: Targeted Tenants | B17: Senior 62+ | C17: 0 | D17: No | E17: 0 | F17: 100% Qualified Occupancy | I17: 47150 | Q17: Taxable | R17: Taxable
A18: Developer | B18: TCB 103-107 West Tremont JV Developer LLC | C18: 0 | D18: 0 | F18: Depreciation Start Date | I18: 46997 | Q18: Variable | R18: Fixed
A19: LEED Certification | B19: Certified | F19: Permanent Loan Closing Date | H19: 47423 | I19: 47239 | P19: Rate Index | Q19: 1-mo SOFR | R19: 10yr Treasury
O20: Current Base Rate | Q20: 0.0362 | R20: 0.0448
A21: OPERATING ENTITY STRUCTURE | O21: Projected Rate Change | Q21: 0 | R21: 0
A22: Operating Partnership / LLC | B22: TCB West Tremont Limited Partnership | C22: 0 | D22: 0 | E22: 0 | G22: Sharing Percentages | O22: Projected Base Rate | Q22: 0.0362 | R22: 0.0448
A23: GP / Managing Members: | F23: Tax Exempt | G23: Income/(Loss) | H23: LIHTC - Fed | I23: Other Credits | J23: LIHTC - State | K23: Historic - State | L23: Cash Flow | M23: Residual | O23: Spread | Q23: 0.0275 | R23: 0.0312
A24: Managing GP | B24: TCB West Tremont GP LLC | C24: 0 | D24: 0 | E24: 0 | F24: No | G24: 9e-05 | H24: 9e-05 | I24: 0 | J24: 0 | K24: 0 | L24: 9e-05 | M24: 0.9 | O24: Liquidity Fee | Q24: 0 | R24: 0
A25: Other GP | B25: 0 | C25: 0 | D25: 0 | E25: 0 | F25: No | G25: 0 | H25: 0 | I25: 0 | J25: 0 | K25: 0 | L25: 0 | M25: 0 | O25: Bond Issuer Fee | Q25: 0 | R25: 0
A26: LP / Investing Members: | O26: Remarketing Fee | Q26: 0 | R26: 0
A27: RBC - | B27: RBC-West Tremont, LLC | C27: 0 | D27: 0 | E27: 0 | F27: No | G27: 0.9999 | H27: 0.9999 | I27: 0 | J27: 0 | K27: 0 | L27: 0.9999 | M27: 0.0999 | O27: Trustee Fee | Q27: 0 | R27: 0
A28: Special LP | B28: RBC Community Investments Manager II, Inc. | C28: 0 | D28: 0 | E28: 0 | F28: No | G28: 1e-05 | H28: 1e-05 | I28: 0 | J28: 0 | K28: 0 | L28: 1e-05 | M28: 0.0001 | O28: Interest Rate Cap Escrow Fee | Q28: 0 | R28: 0
A29: RBC - | C29: #REF! | D29: #REF! | E29: 0 | F29: No | G29: 0 | H29: 0 | I29: 0 | J29: 0 | K29: 0 | L29: 0 | M29: 0 | O29: LOC Fee | Q29: 0.0011 | R29: 0
A30: Other LP | B30: 0 | C30: 0 | D30: 0 | E30: 0 | F30: No | G30: 0 | H30: 0 | I30: 0 | J30: 0 | K30: 0 | L30: 0 | M30: 0 | O30: Servicing Fee | Q30: 0 | R30: 0
G31: 1 | H31: 1 | I31: 0 | J31: 0 | K31: 0 | L31: 1 | M31: 1 | O31: Total Annual Ongoing Fees | Q31: 0.0286 | R31: 0.0312
O33: Projected Note Rate | Q33: 0.0648 | R33: 0.076
A34: Construction Financing Assumptions | H34: Summary of Tax Credit Equity
D35: Interest Rate | E35: Loan Term | K35: Tax Credits to | M35: Capital | O35: Underwriting Adjustment | Q35: 0 | R35: 0
A36: Financing Vehicle | B36: Total | C36: Interest Rate | D36: Calculation | E36: (Months) | K36: fund | L36: $/Credit | M36: Contribution
A37: Bank of New York | B37: 24400000 | C37: 0.0648 | D37: 1-mo SOFR + 286 bps | E37: 36 | O37: Underwriting Interest Rate | Q37: 0.0648 | R37: 0.076
A38: HPD SARA | B38: 28202240 | C38: 0.0025 | D38: Fixed | E38: 36 | H38: Low Income Housing Tax Credits | K38: 17668230 | L38: 0.97750018 | M38: 17270698
B39: 0 | C39: 0 | D39: 0 | E39: 0 | H39: Historic Tax Credits | K39: 0 | L39: 0 | M39: 0
B40: 0 | C40: 0 | D40: 0 | E40: 0 | H40: Other Credits | K40: 0 | L40: 0 | M40: 0 | O40: Interest Rate Floor | Q40: 0 | R40: 0
B41: 0 | C41: 0 | D41: 0 | E41: 0 | H41: Low Income Housing Tax Credits - State | K41: 0 | L41: 0 | M41: 0 | O41: Interest Rate CAP | Q41: 0 | R41: 0
A42: RBC Loan | B42: 0 | C42: 0 | D42: 0 | E42: 0 | H42: Historic Tax Credits - State | K42: 0 | L42: 0 | M42: 0
...

Sheet 3.PropInt (LOAD)
A1: INSTRUCTIONS FOR PROPINT
A2: 1. COPY AND PASTE ALL CELLS AS VALUES. DELETE ROWS 1-3
A3: 2. LOAD SLOW IN BATCH LOAD
A4: vCode | B4: vIntType | C4: iInt
A5: ='CASE INPUTS'!$B$10 -> westrmt | B5: Total Units | C5: =DATA!B$9 -> 97
A6: ='CASE INPUTS'!$B$10 -> westrmt | B6: LIHTC Units | C6: =DATA!B$10 -> 96
A7: ='CASE INPUTS'!$B$10 -> westrmt | B7: Manager Units | C7: =DATA!B$11 -> 1
A8: ='CASE INPUTS'!$B$10 -> westrmt | B8: Total Buildings | C8: =DATA!B$12 -> 1
A9: ='CASE INPUTS'!$B$10 -> westrmt | B9: Market Units | C9: =DATA!E$11 -> 0

Sheet 4.ProjOccupancy (LOAD)
A1: vCode | B1: dtPeriod | C1: iOccLIHTCUnits | D1: iOccMarketUnits | E1: iOccUnits | F1: INSTRUCTIONS FOR PROJECT OCCUPANCY
A2: ='CASE INPUTS'!$B$10 -> westrmt | B2: =DATA!G124 -> 46753 | C2: =DATA!H124 -> 0 | D2: =DATA!P124 -> 0 | E2: =C2+D2 -> 0 | F2: DRAG DOWN EACH FORMULAS FROM ROW 2 UNTIL ROW 49
F3: DELETE ALL UNHIGHLIGHTED ROWS
F4: COPY PASTE ALL CELLS AS VALUES THEN DELETE THIS COLUMN (F) BEFORE BATCH LOADING
F49: <-- ROW 49

Sheet 5.Projection_Annual (LOAD)
A1: vCode | B1: dtProjections | C1: vVersion | D1: iYear | E1: mInvestorTaxInc | F1: mStateCredit | G1: mFedCredit | H1: INSTRUCTIONS FOR PROJECTION ANNUAL
A2: ='CASE INPUTS'!$B$10 -> westrmt | B2: ='CASE INPUTS'!$B$8 -> 46199 | C2: Closed | D2: =DATA!A413 -> 2026 | E2: =DATA!C413 -> 0 | F2: =DATA!I413 -> 0 | G2: =DATA!F413 -> 0 | H2: PULL DOWN THE FORMULAS UNTIL ROW 20
A3: ='CASE INPUTS'!$B$10 -> westrmt | B3: ='CASE INPUTS'!$B$8 -> 46199 | C3: Closed | D3: =DATA!A414 -> 2027 | E3: =DATA!C414 -> -5832 | F3: =DATA!I414 -> 0 | G3: =DATA!F414 -> 0 | H3: COPY PASTE ALL CELLS AS VALUES THEN DELETE THIS COLUMN (H) BEFORE BATCH LOADING
A4: ='CASE INPUTS'!$B$10 -> westrmt | B4: ='CASE INPUTS'!$B$8 -> 46199 | C4: Closed | D4: =DATA!A415 -> 2028 | E4: =DATA!C415 -> -9865917 | F4: =DATA!I415 -> 0 | G4: =DATA!F415 -> 0
A5: ='CASE INPUTS'!$B$10 -> westrmt | B5: ='CASE INPUTS'!$B$8 -> 46199 | C5: Closed | D5: =DATA!A416 -> 2029 | E5: =DATA!C416 -> -2910888 | F5: =DATA!I416 -> 0 | G5: =DATA!F416 -> 1766823
A6: ='CASE INPUTS'!$B$10 -> westrmt | B6: ='CASE INPUTS'!$B$8 -> 46199 | C6: Closed | D6: =DATA!A417 -> 2030 | E6: =DATA!C417 -> -2722713 | F6: =DATA!I417 -> 0 | G6: =DATA!F417 -> 1766823
A7: ='CASE INPUTS'!$B$10 -> westrmt | B7: ='CASE INPUTS'!$B$8 -> 46199 | C7: Closed | D7: =DATA!A418 -> 2031 | E7: =DATA!C418 -> -2724027 | F7: =DATA!I418 -> 0 | G7: =DATA!F418 -> 1766823
A8: ='CASE INPUTS'!$B$10 -> westrmt | B8: ='CASE INPUTS'!$B$8 -> 46199 | C8: Closed | D8: =DATA!A419 -> 2032 | E8: =DATA!C419 -> -2724881 | F8: =DATA!I419 -> 0 | G8: =DATA!F419 -> 1766823
A9: ='CASE INPUTS'!$B$10 -> westrmt | B9: ='CASE INPUTS'!$B$8 -> 46199 | C9: Closed | D9: =DATA!A420 -> 2033 | E9: =DATA!C420 -> -2761257 | F9: =DATA!I420 -> 0 | G9: =DATA!F420 -> 1766823
A10: ='CASE INPUTS'!$B$10 -> westrmt | B10: ='CASE INPUTS'!$B$8 -> 46199 | C10: Closed | D10: =DATA!A421 -> 2034 | E10: =DATA!C421 -> -2783585 | F10: =DATA!I421 -> 0 | G10: =DATA!F421 -> 1766823
A11: ='CASE INPUTS'!$B$10 -> westrmt | B11: ='CASE INPUTS'!$B$8 -> 46199 | C11: Closed | D11: =DATA!A422 -> 2035 | E11: =DATA!C422 -> -2898325 | F11: =DATA!I422 -> 0 | G11: =DATA!F422 -> 1766823
A12: ='CASE INPUTS'!$B$10 -> westrmt | B12: ='CASE INPUTS'!$B$8 -> 46199 | C12: Closed | D12: =DATA!A423 -> 2036 | E12: =DATA!C423 -> -2946673 | F12: =DATA!I423 -> 0 | G12: =DATA!F423 -> 1766823
A13: ='CASE INPUTS'!$B$10 -> westrmt | B13: ='CASE INPUTS'!$B$8 -> 46199 | C13: Closed | D13: =DATA!A424 -> 2037 | E13: =DATA!C424 -> -2977828 | F13: =DATA!I424 -> 0 | G13: =DATA!F424 -> 1766823
A14: ='CASE INPUTS'!$B$10 -> westrmt | B14: ='CASE INPUTS'!$B$8 -> 46199 | C14: Closed | D14: =DATA!A425 -> 2038 | E14: =DATA!C425 -> -3047890 | F14: =DATA!I425 -> 0 | G14: =DATA!F425 -> 1766823
A15: ='CASE INPUTS'!$B$10 -> westrmt | B15: ='CASE INPUTS'!$B$8 -> 46199 | C15: Closed | D15: =DATA!A426 -> 2039 | E15: =DATA!C426 -> -3101259 | F15: =DATA!I426 -> 0 | G15: =DATA!F426 -> 0
... A19: ='CASE INPUTS'!$B$10 -> westrmt | B19: ='CASE INPUTS'!$B$8 -> 46199 | C19: Closed | D19: =DATA!A430 -> 2043 | E19: =DATA!C430 -> -3225663 | F19: =DATA!I430 -> 0 | G19: =DATA!F430 -> 0
A20: ='CASE INPUTS'!$B$10 -> westrmt | B20: ='CASE INPUTS'!$B$8 -> 46199 | C20: Closed | D20: =DATA!A431 -> 2044 | E20: =DATA!C431 -> 0 | F20: =DATA!I431 -> 0 | G20: =DATA!F431 -> 0 | H20: <-- ROW 20

Sheet 6.TXFINANCIAL&INFLATOR (LOAD) 
A1: EXCEL MAIN | O1: MAPPING PART SEND TO RBC.integratec.biz
W2: SOP FOR SENDING PROJECTED IS LOAD TO DMS
W3: Send First Response email to client + CC DMS ([RBC@integratec.biz]), Lindsey O'Connor, and Jessica Gouge
W5: EMAIL TEMPLATE
W6: Hello, [Client]
W7: I have confirmed that I have received all the necessary documentation to set up this deal. This setup will be completed within 5 business days.
W8: Data Management Services (DMS) will complete the Projected IS load for this deal. This email sends the required data to their queue; the document is attached, and your RBC@integratec.biz address is included. Once my portion of the setup is complete, I will validate the DMS load before confirming full setup completion.
W9: Thank you!
A27: STEP 1
A28: USE EXCEL MAIN TO ARRANGE THE DATA GIVEN BY CLIENT ( PROJECTED IS FILE)
A29: A NEW FILE WILL BE CREATED WITH THE NAME THAT WAS INITIALY SET UP IN EXCEL MAIN APP
A31: STEP 2
A32: OPEN THE NEW FILE CREATED BY EXCEL MAIN
A33: CREATE 2 NEW TABS TO PASTE THE DATA
A34: FIRST TAB : TX FINANCIAL
A35: SECOND TAB: INFLATOR
A38: STEP 3 | G38: TXFinancial | M38: USE BATCH LOADER
A40: COPY COLUMN C - H WITH HEADERS AND PASTE TO TX FINANCIAL TAB | G40: vCode | H40: dtEntry | I40: vAccount | J40: mAmount | K40: iBook | L40: iType | M40: TO LOAD SLOW
A42: STEP 4
A43: COPY COLUMN O , P , Q & S RENAME HEADERS TO APPROPRIATE FORMAT | G43: Inflator | M43: USE BATCH LOADER
G44: vCode | H44: vType | I44: dtInflator | J44: nPercent | M44: TO LOAD SLOW
A46: STEP 5
A47: USE THE FILE CREATED BY EXCEL MAIN APP AND SEND TO BATCH LOAD TO LOAD SLOW TXFINANCIAL AND INFLATOR
A52: WORQ WILL BE HANDLED BY DMS
A53: COPY COLUMN J - M WITH OUT HEADERS AND PASTE TO MAPPING TAB | G53: Mapping | H53: No Headers | M53: USE WORK Q CENTRAL
G54: Filter out and remove zeros, words and blanks | M54: THIS WIL BE LOADED BY DMS

Sheet 7.Rents (LOAD)
A1: INSTRUCTIONS FOR RENTS
A2: 1. DRAG DOWN THE FORMULA FOR COLUMN E > G THEN B
A3: 2. DRAG DOWN THE FORMULAS UNTIL ROW 50
A4: 3. DRAG DOWN ALL REMAINING COLUMNS WITH FORMULAS
A5: 4. DELETE ALL UNHILIGHTED ROWS
A6: 5. COPY AND PASTE ALL CELLS AS VALUES THEN DELETE COLUMN B AND ROWS 1-7
A7: 6. LOAD SLOW IN BATCH LOAD
A8: vCode | B8: Drag this formula down after draging down column E. This will determine the “vType” in column C, indicating whether the units are LIHTC or Market. | C8: vType | D8: fAffordability | E8: fBedrooms | F8: fBathrooms | G8: iNumberUnits | H8: mRent | I8: dtRentDate | J8: mMaxRent | K8: mMaxUtilAllow | L8: iSquareFootage | M8: vnotes
A9: ='CASE INPUTS'!$B$10 -> westrmt | B9: =DATA!C501 -> LIHTC | C9: {=IF(AND(B9="LIHTC",G9>0),INDEX('CASE INPUTS'!$A$32:$A$41,E9+1),IF(AND(B9="Market",G9>0),INDEX('CASE INPUTS'!$A$42:$A$51,E9+1),IF(AND(B9="Converted",G9>0),"Converted",IF(AND(B9="Efficiency",G9>0),"Efficiency",IF(AND(B9="Employee",G9>0),"Employee",IF(AND(B9="Manager",G9>0),"Manager",IF(AND(B9="Other",G9>0),"Other","")))))))} -> LI-Studio | D9: =DATA!F501 -> 0.3 | E9: =DATA!A501 -> 0 | F9: =DATA!B501 -> 1 | G9: =DATA!H501 -> 29 | H9: =DATA!K501 -> 2781 | I9: ='CASE INPUTS'!$B$8 -> 46199 | J9: =DATA!R501 -> 850 | K9: =DATA!Q501 -> 0 | L9: =DATA!G501 -> 436

Sheet 8.Event Dates (LOAD)
A1: INSTRUCTIONS FOR EVENT DATES
A2: 1. COPY AND PASTE ALL CELLS AS VALUES THEN DELETE ROWS 1-3
A3: 2. LOAD SLOW IN BATCH LOAD
A4: vCode | B4: vEventType | C4: vEvent | D4: vDateType | E4: dtEvent | F4: dtEntry
A5: ='CASE INPUTS'!$B$10 -> westrmt | B5: LPA | C5: Closing | D5: Actual | E5: ='CASE INPUTS'!$B$8 -> 46199 | F5: ='CASE INPUTS'!$B$11 -> 07/30/2026
A6: ='CASE INPUTS'!$B$10 -> westrmt | B6: Construction | C6: Start | D6: Projected | E6: =DATA!I7 -> 46174 | F6: ='CASE INPUTS'!$B$11 -> 07/30/2026
A7: ='CASE INPUTS'!$B$10 -> westrmt | B7: Lease Up | C7: End | D7: Projected | E7: =DATA!I17 -> 47150 | F7: ='CASE INPUTS'!$B$11 -> 07/30/2026
A8: ='CASE INPUTS'!$B$10 -> westrmt | B8: Perm Loan | C8: Closed | D8: Projected | E8: =DATA!I19 -> 47239 | F8: ='CASE INPUTS'!$B$11 -> 07/30/2026
A9: ='CASE INPUTS'!$B$10 -> westrmt | B9: Replacement Reserve | C9: Start | D9: Projected | E9: =DATA!B646 -> 46997 | F9: ='CASE INPUTS'!$B$11 -> 07/30/2026
A10: ='CASE INPUTS'!$B$10 -> westrmt | B10: Stabilization | C10: Achieved | D10: Projected | E10: ='CASE INPUTS'!B9 -> 47239 | F10: ='CASE INPUTS'!$B$11 -> 07/30/2026

Sheet 9.Investor (LOAD)
B1: INSTRUCTIONS FOR INVESTOR
B2: 1. DO NOT CHANGE INVESTOR CODE UNLESS STATED IN THE CASE
B3: 2. COPY AND PASTE ALLL CELLS AS VALUES THEN DELTE ROWS 1 -4
B4: 3. LOAD SLOW IN BATCH LOAD | E4: =DATA!G27 -> 0.9999
A5: vCode | B5: vInvestor | C5: iyear | D5: vsource | E5: fOwnership
A6: ='CASE INPUTS'!$B$10 -> westrmt | B6: rbcinven | C6: ='CASE INPUTS'!$B$8 -> 46199 | D6: Manual | E6: =E4 * 100 -> 99.99

Sheet 10-Property(Checker)
A1: Tenancy | B1: Property Type | C1: Partnership Name | D1: Credit Type: | E1: Status: | F1: Location Code | G1: Investment Type | H1: Region | I1: Scattered | J1: Special Needs | K1: City | L1: State | M1: County | N1: Federal LIHTC | O1: State LIHTC | P1: State Historic: | Q1: Federal Historic
A2: =DATA!B17 -> Senior 62+ | B2: =DATA!B15 -> High-Rise | C2: =DATA!B22 -> TCB West Tremont Limited Partnership | D2: =DATA!B14 -> New Construction | E2: ='CASE INPUTS'!$B14 -> 0 | F2: =DATA!B16 -> Urban | G2: =DATA!C455 -> 0.09 | H2: ='CASE INPUTS'!$B12 -> 0 | I2: =DATA!D15 -> No | J2: =DATA!D17 -> No | K2: =DATA!B6 -> Bronx | L2: =DATA!B8 -> NY | M2: =DATA!B7 -> Bronx | N2: =IF(N3>0,"Yes","No") -> Yes | O2: =IF(O3>0,"Yes","No") -> No | P2: =IF(P3>0,"Yes","No") -> No | Q2: =DATA!O454 -> No
N3: =DATA!H27 -> 0.9999 | O3: =DATA!J27 -> 0 | P3: =DATA!K27 -> 0 | Q3: =DATA!O454 -> No

Sheet 11.Property(UPDATE)
A1: INSTRUCTIONS FOR PROPERTY
A2: 1. IF RBC HAS ALREADY ENTERED THESE INPUTS SKIP THIS PART IF NO INPUTS PROCEED TO STEP 2 - 4
A3: 2. COPY AND PASTE ALL CELLS AS VALUES
A4: 3. DELETE ROWS 1-3
A5: 4. LOAD SLOW IN BATCH LOAD
A6: vCode | B6: vCity | C6: vState
A7: ='CASE INPUTS'!$B$10 -> westrmt | B7: =DATA!B6 -> Bronx | C7: =DATA!B8 -> NY

Sheet 12.TXPROP (LOAD)
A1: INSTRUCTIONS FOR TXPROP | I1: 0.9999 | J1: 0 | K1: 0
A2: 1. COPY AND PASTE ALL CELLS AS VALUES THEN DELETE ROWS 1-3
A3: 3. LOAD SLOW IN BATCH LOAD
A4: vCode | B4: vPropType | C4: vPartnershipName | D4: vLocationCode | E4: vRegion | F4: vScattered | G4: vSpecialNeeds | H4: vCounty | I4: vFedLIHTC | J4: vStateLIHTC | K4: vStateHistoric | L4: vFedHistoric
A5: ='CASE INPUTS'!$B$10 -> westrmt | B5: =DATA!B15 -> High-Rise | C5: =DATA!B22 -> TCB West Tremont Limited Partnership | D5: =DATA!B16 -> Urban | E5: ='CASE INPUTS'!$B$12 -> 0 | F5: =DATA!D15 -> No | G5: =DATA!D17 -> No | H5: =DATA!B7 -> Bronx | I5: =IF(I1>0,"Yes","No") -> Yes | J5: =IF(J1>0,"Yes","No") -> No | K5: =IF(K1>0,"Yes","No") -> No | L5: =DATA!O454 -> No

Sheet 13.EquityInstallments (LOAD)
A1: INSTRUCTIONS FOR EQUITYINSTALLMENTS
A2: 1. GO TO THE EQUITY INSTALLMENTS SCREEN
A3: **IMPORTANT NOTE IF THERE IS A PAYMENT DETAIL TAKE A SCREEN SHOT, IT WILL BE RE ADDED AFTER LOADING TAB 14
A4: 2. DELETE ALL EXISTING RECORDS FOR THIS PROPERTY ON EQUITY INSTALLMENTS SCREEN
A5: 3. COPY AND PASTE ALL CELLS AND VALUES THEN DELETE ROWS 1- 6
A6: 4. LOAD SLOW IN BATCH LOAD
A7: vCode | B7: vOwnerCode | C7: dtEntry | D7: vType
A8: ='CASE INPUTS'!$B$10 -> westrmt | B8: rbcinven | C8: ='CASE INPUTS'!$B$8 -> 46199 | D8: Equity
A9: ='CASE INPUTS'!$B$10 -> westrmt | B9: rbcinven | C9: ='CASE INPUTS'!$B$8 -> 46199 | D9: Developer Fee

Sheet 14.Commitment (LOAD)
A1: UID FOR EQUITY : | C1: INSTRUCTIONS
A2: UID FOR DEVELOPER FEE : | C2: 1. DRAG FORMULAS DOWN ONLY UNTIL THE EQUITY SECTION. DO NOT EXTEND FORMULAS BEYOND THE EQUITY–DEVELOPER FEE DIVIDER. | D2: 4. DELETE ALL UNHIGHLIGHTED ROWS
C3: 2. IN SQL GET THE UID FOR THE EQUITY AND DEVELOPER FEE TYPE TO GET THE "iEquityInstallID" FOR EQUITY AND DEVELOPER FEE USE QUERRY BELOW | D3: 5. ADD 'vInstallnumber' FOR EQUITY (ASC–DESC); ADD 'vInstallnumber' FOR FEE (ASC–DESC); *SEPARATE NUMBERING FOR EQUITY TYPE AND DEVELOPER FEE.
C4: ="USE RBC" & CHAR(10) & "select * from EquityInstallments" & CHAR(10) & "where vcode = '" & 'CASE INPUTS'!B10 & "'" -> USE RBC select * from EquityInstallments where vcode = 'westrmt' | D4: 6. COPY AND PASTE ALL CELLS AS VALLUES THEN PASTE.
A5: EQUITY | B5: ALWAYS rbcinven | C5: 3. COPY AND PASTE UID OF EQUITY IN CELL "B1" COPY AND PASTE UID OF DEVELOPER FEE IN CELL "B2" DRAG THE FORMULA DOWN UNDER iEquityInstallID, ENSURING EACH CELL HAS ITS OWN ID. | D5: 7. DELETE ROWS 1-5 and 27. AFTER FINALIZING LOAD SLOW IN BATCH LOAD | G5: ALWAYS "NET EQUITY" | H5: SAME WITH COMMITMENT DATE
A6: vCode | B6: vOwnerCode | C6: dtCommitment | D6: vInstallNmbr | E6: mAmount | F6: vConditions | G6: vType | H6: dtDue | I6: iEquityInstallID
A7: ='CASE INPUTS'!$B$10 -> westrmt | B7: rbcinven | C7: =DATA!E85 -> 46174 | D7: 1 | E7: =DATA!G85 -> 3454140 | F7: =DATA!A85 -> Partnership Closing, AHAP | G7: Net Equity | H7: =C7 -> 46174 | I7: =B$1 -> 0
G8: Net Equity
G9: Net Equity
G10: Net Equity
G11: Net Equity
G12: Net Equity
G13: Net Equity
G14: Net Equity
G15: Net Equity
G16: Net Equity
G17: Net Equity
G18: Net Equity
A27: DO NOT DRAG FORMULAS DOWN HERE TO THE EQUITY - DEVELOPER FEE DIVDER
A28: ='CASE INPUTS'!$B$10 -> westrmt | B28: rbcinven | C28: =DATA!D104 -> 46174 | D28: 1 | E28: =DATA!G104 -> 727500 | F28: =DATA!B104 -> Partnership Closing, AHAP | G28: Net Equity | H28: =C28 -> 46174 | I28: =B$2 -> 0
G29: Net Equity
G30: Net Equity
G31: Net Equity
G32: Net Equity
G33: Net Equity
G34: Net Equity
G35: Net Equity
G36: Net Equity
G37: Net Equity
G38: Net Equity
G39: Net Equity

Sheet 15. Payment (LOAD)
A1: INSTRUCTIONS FOR PAYMENT
A2: 1. PROCEED WITH THIS LOAD TAB WHEN A PAYMENT DETAIL IS SET UP.
A3: 2. OPEN YOUR SAVED SCREEN SHOT FOR THE PAYMENT DETAILS
A4: 3.DO NOT CHANGE 'vOwnercode: rbcinven' UNLESS STATED IN THE CASE
A5: 4. ADD THE PAYMENT DETAILS:
A6: IF PAYMENT DETAILS IS ADDED IN EQUITY GET THE iEquityInstallID in TAB 14 - CELL B1
A7: IF PAYMENT DETAILS IS ADDED IN DEVELOPER GET THE iEquityInstallID in TAB 14 - CELL B2
A8: 5. ADD THE INSTALLMENT NUMBER BASED ON THE ORIGINAL INPUT INSTALLMENT NUMBER.
A9: 6. COPY AND PASTE ALL CELSS AS VALUES AND DELETE ROWS 1-10
A10: 7. LOAD SLOW IN BATCH LOAD
A11: vCode | B11: vOwnerCode | C11: dtPayment | D11: vInstallment | E11: mAmountPaid | F11: mOther | G11: vReason | H11: iEquityInstallID
A12: ='CASE INPUTS'!$B$10 -> westrmt | B12: rbcinven | C12: 46008 | D12: 1 | E12: 2779112 | F12: NULL | G12: Net Equity | H12: 3743

Sheet 16.Projection (LOAD)
A1: INSTRUCTIONS FOR PROJECTION | O1: =DATA!D486 -> 0.09 | Q1: =DATA!D469+DATA!E469 -> 61983445 | Y1: =DATA!H240 -> 0.050000699
A2: 1. COPY AND PASTE ALL CELLS AS VALUES, THEN DELETE ROWS 1-3
A3: 2. LOAD SLOW IN BATCH LOAD
A4: vCode | B4: dtProjections | C4: vVersion | D4: iProjUnits | E4: iProjBldgs | F4: fDeprecLifeBldgs | G4: vDeprecMethodBldgs | H4: fDeprecLifePersProp | I4: vDeprecMethodPersProp | J4: mFedCredPrice | K4: mAnnualResRep | L4: mPercentIncResRep | M4: mDevCosts | N4: fCreditRate9 | O4: fCreditRate4 | P4: mEligibleBasis9 | Q4: mEligibleBasis4 | R4: mEstEligibleBasisLIHTC | S4: mEstExpectedFedLIHTC | T4: mDeferredDevFee | U4: mAnnCredit | V4: mEstEquity | W4: fStaticDSC | X4: fIRR | Y4: fLIHTCVacancy | Z4: mOpExpUnit | AA4: mOpRes | AB4: mRRRes
A5: ='CASE INPUTS'!$B$10 -> westrmt | B5: ='CASE INPUTS'!$B$8 -> 46199 | C5: Closed | D5: =DATA!B9 -> 97 | E5: =DATA!B12 -> 1 | F5: =DATA!I177 -> 30 | G5: SL | H5: =DATA!I186 -> 5 | I5: SL | J5: =ROUNDUP(DATA!B74, 2) -> 0.98 | K5: =DATA!C646 -> 400 | L5: =DATA!E646 -> 1.03 | M5: =DATA!C447 -> 74476866 | N5: =IF(ROUND(O1,5)=0.09, O1, "") -> 0.09 | O5: =IF(ROUND(O1,5)=0.04, O1, "") | P5: =IF(O1=0.09, Q1, "") -> 61983445 | Q5: =IF(O1=0.04, Q1, "") | R5: =DATA!D481+DATA!E481 -> 80578478 | S5: =DATA!K38 -> 17668230 | T5: =DATA!B76 -> 4426326 | U5: =DATA!C487 -> 7252063 | V5: =DATA!G97 -> 17270698 | W5: =ROUNDUP(DATA!B81, 2) -> 1.26 | X5: =DATA!C79 -> 0.066164356 | Y5: =ROUND(Y1*100,0) -> 5 | Z5: =DATA!D629 -> 11535 | AA5: =DATA!C446 -> 1416136 | AB5: =DATA!D646 -> 38800

Sheet 17.PartnerAgree (UPDATE)
A1: INSTRUCTIONS FOR PARTNERAGREE
A2: 1. EASILY ADDED IN MANUALLY ON SCREEN OR UPDATE IN BATCH LOAD
A3: 2. COPY AND PASTE ALL CELLS AS VALUES AND DELETE ROWS 1-4
A4: 3. UPDATE IN BATCH LOAD
A5: vCode | B5: mResRepAnnualAmountperUnit
A6: ='CASE INPUTS'!$B$10 -> westrmt | B6: =DATA!C646 -> 400

Sheet 18.Loan (LOAD)
A1: INSTRUCTIONS FOR LOAN
A2: 1. GET THE INTEREST RATE FROM THE CASE DETAILS AND ADD IN vNOTES
A3: 2. GET vVENDOR IN VENDOR SCREEN IF NO vVENDOR IN VENDOR SCREEN ADD VENDOR AS LENDER
A4: 3. IF iAMORTTERM AND iLOANTERM ARE PLACED AS YEARS CONVERT TO MONTHs BY MULTIPLYING BY 12
A5: 4. AFTER FINALIZING COPY AND PASTE ALL CELLS AS VALUES AND DELETE ROWS 1-6
A6: 5. LOAD SLOW IN BATCH LOAD
A7: vCode | B7: vVendor | C7: mOrigLoanAmt | D7: iAmortTerm | E7: iLoanTerm | F7: vNotes
A8: ='CASE INPUTS'!$B$10 -> westrmt | B8: ='CASE INPUTS'!$B$13 -> mtbank | C8: 1925000 | D8: 420 | E8: 216 | F8: Interest rate: %

Sheet 19.Collection Rules (LOAD)
B1: INSTRUCTIONS FOR COLLECTION RULES
B2: 1. COPY AND PASTE ALL CELLS AS VALUES
B3: 2. DELETE ROWS 1-3 AND COLUMN B
A4: vCode | B4: 3. LOAD SLOW IN BATCH LOAD | C4: iType_ID | D4: dtStart | E4: dtEnd | F4: vFrequency | G4: vCurrentPeriod | H4: dtCurrentDue
A5: ='CASE INPUTS'!$B$10 -> westrmt | B5: Audit = | C5: 4 | D5: ='CASE INPUTS'!$B$8 -> 46199 | F5: Annually | G5: =IF(D5="", "", DATE(YEAR(D5), 12, 31)) -> 46387 | H5: =DATE(YEAR(G5) + 1, 2, 28) -> 46446
A6: ='CASE INPUTS'!$B$10 -> westrmt | B6: 8609 = | C6: 30 | D6: ='CASE INPUTS'!$B$8 -> 46199 | F6: One-Time | G6: 1 | H6: ='CASE INPUTS'!B8 -> 46199
A7: ='CASE INPUTS'!$B$10 -> westrmt | B7: Cost Cert = | C7: 33 | D7: ='CASE INPUTS'!$B$8 -> 46199 | F7: One-Time | G7: 1 | H7: ='CASE INPUTS'!B8 -> 46199

Sheet 20.Notification_Rule (LOAD)
A1: INSTRUCTIONS FOR NOTIFICATION_RULE
A2: 1. FROM COLLECTION RULES SCREEN PASTE THE RECORD ID OF THE DATA TYPE "AUDITS" IN CELLS (A6 - A9)
A3: 2. COPY AND PASTE ALL CELLS AS VALUES THEN DELETE ROWS 1-4
A4: 3. LOAD SLOW IN BATCH LOAD
A5: iCollRuleID | B5: vType | C5: iLag | D5: iEmailID | E5: bActive | F5: vNotes
B6: Email | C6: -90 | D6: 42 | E6: booltrue
B7: Email | C7: -59 | D7: 42 | E7: booltrue
B8: Email | C8: -28 | D8: 42 | E8: booltrue
B9: Email | C9: -14 | D9: 42 | E9: booltrue

Sheet VERIFICATION STEPS
A1: PROPERTY | C1: FALSE
A2: 1. Make sure these fields are added correctly and contain no blank values:
A3: vPropType
A4: vPartnershipName
A5: vLocationCode
A6: vRegion
A7: vScattered
A8: vSpecialNeeds
A9: vCounty
A10: vFedLIHTC
A11: vStateLIHTC
A12: vStateHistoric
A13: vFedHistoric
A15: RENTS | C15: FALSE
A16: 1. Make sure you have completed your part in Rents, then confirm if DMS have loaded projeceted IS in SQL.
A17: Use Querry to check for Projected IS: USE RBC select * from vStaging_Journal_Entry where vCode = ‘your prop’ and vSource = ‘Projected IS’
A18: To check if you have succesfully loaded your Rents load use querry : USE RBC select * from rents where vcode ='your prop'
A19: 2. Run the Rent Matrix Report in Reports (Aurelia) and add your property.
A20: 3. Rent load should appear in the downloaded Excel report.
A21: 4. If everything is loaded in correctly but still nothings shows in the report confirm with RBC if they have done their part for Rents screen
A23: EVENT DATES | C23: FALSE
A24: Event dates are complete and correctly generated
A26: COLLECTION RULES | C26: FALSE
A27: Make sure that dates are entered in correctly
A28: Email types are properly assigned
A29: Notification lags properly added
A31: EQUITY INSTALLMENTS | C31: FALSE
A32: 1. There must 2 records for Equity Installments
A33: Equity and Developer Fee
A34: 2. No missing or duplicate commitment details

Sheet REFERENCE TAB
A1: Source Doc | B1: Source Doc2 | C1: Source Field | D1: Source Field location | E1: Table | F1: Column | G1: Notes/Criteria | H1: IC Screen | I1: IC Field
B3: Case details | D3: Property Information section | E3: PropInt | F3: vCode | H3: Totals (Aurelia) | I3: Asset Code
E4: PropInt | F4: vIntType | G4: Where vIntTyype = | H4: Totals (Aurelia) | I4: Total Type
G6: • Total Units
G7: • LIHTC Units
G8: • Managers Units
G9: • Total Buildings
G10: • Market Units
C11: B9 Number of Total Units | E11: PropInt | F11: iInt | H11: Totals (Aurelia) | I11: Number
D14: Equity Funding & Lease up | E14: ProjOccupancy | F14: vCode | H14: Projected Occupancy (Aurelia) | I14: Property Code
D15: Assumptions section
C16: G124 and down, | E16: ProjOccupancy | F16: dtPeriod | H16: Projected Occupancy (Aurelia) | I16: Date Period
C17: Month column
C18: H124 and down, Revenue units column | E18: ProjOccupancy | F18: iOccLIHTCUnits | G18: Remove rows where value = 0 | H18: Projected Occupancy (Aurelia) | I18: Occupied Units (LIHTC)
C19: P124 and down, Current column | E19: ProjOccupancy | F19: iOccMarketUnits | G19: Remove rows where value = 0 | H19: Projected Occupancy (Aurelia) | I19: Occupied Units (Market)
E20: ProjOccupancy | F20: iOccUnits | G20: SUM of iOccLIHTCUnits and iOccMarketUnits | H20: Projected Occupancy (Aurelia) | I20: Occupied Units
D22: Projected Taxable Income/(Loss) Section | E22: Projection_Annual | F22: vCode | H22: Proeprty Code | I22: Property Code
B23: Case details | C23: LPA/LT – Closing – Actual | F23: dtProjections | H23: Projection Date | I23: Projection Date
B24: NA | F24: vVersion | G24: Always "Closed" | H24: Projections (Aurelia) | I24: Description
C25: A413 and down, Year | F25: iYear | H25: Annual Projections tab at bottom of screen | I25: Year
C26: C413 and down, Projected Taxable Income (Loss) | F26: mInvestorTaxInc | H26: Annual Projections tab at bottom of screen | I26: Investor Tax Income column
C27: I413 and down, Projected State Tax Credits | F27: mStateCredit | H27: Annual Projections tab, click "Open all" | I27: State credit
C28: F413 and down, Projected Federal Housing Tax Credits | F28: mFedCredit | H28: Annual Projections tab at bottom of screen | I28: Fed Credits column
B30: Case details | D30: Rental Income Section | E30: Rents | F30: vCode | H30: Field not available on front end.
C31: C498 down, Type | F31: vType | G31: IF UNITS ARE LIHTC USE: | H31: Rent Overview (Aurelia) - Rent Detail section | I31: Type
G32: • LI-Studio
G33: • LI-1BR
G34: • LI-2BR
G37: IF UNITS ARE MARKET OR NON-QUALIFIED TYPE USE:
G38: • Mkt-Studio
G39: • Mkt-1BR
G40: • Mkt-2BR
G42: Other types like Converted, Efficiency, or Employee may be used. Check with Beth or Paula if clarification is needed.
C43: F501 down, % of AMI | F43: fAffordability | H43: Rent Overview (Aurelia) - Rent Detail section | I43: AMI
C44: A501 down, Bedrms | F44: fBedrooms | H44: Rent Overview (Aurelia) - Rent Detail section | I44: # Bed
C45: B501 down, Baths | F45: fBathrooms | H45: Rent Overview (Aurelia) - Rent Detail section | I45: # Bath
C46: H501 down, # of Units | F46: iNumberUnits | H46: Rent Overview (Aurelia) - Rent Detail section | I46: # Units
C47: K501 down, Net Rent | F47: mRent | H47: Rent Overview (Aurelia) - Rent Detail section | I47: Proj.Rent
B48: Case details | C48: LPA/LT – Closing – Actual | F48: dtRentDate | H48: Field not available on front end.
C49: R501 down, Max LIHTC NET Rent | F49: mMaxRent | H49: Field not available on front end.
...
